class Exception:
    def __init__(self):
        pass